<?xml version="1.0" ?>
<!-- =================================================================================== -->
<!-- |    This document was autogenerated by xacro from ur10_robot.urdf.xacro          | -->
<!-- |    EDITING THIS FILE BY HAND IS NOT RECOMMENDED                                 | -->
<!-- =================================================================================== -->
<robot name="one_link" xmlns:xacro="http://ros.org/wiki/xacro">
  <gazebo>
    <plugin filename="libgazebo_ros_control.so" name="ros_control">
      <robotNamespace>/one_link</robotNamespace>
      <robotSimType>gazebo_ros_control/DefaultRobotHWSim</robotSimType>
    </plugin>
  </gazebo>

  <link name="world"/>
  <joint name="world_joint" type="fixed">
    <parent link="world"/>
    <child link="base_link"/>
    <origin rpy="-1.5708 0.0 0.0" xyz="0.0 0.0 0.1"/>
  </joint>

  <link name="base_link">
    <visual>
      <geometry>
        <box size="0.2 0.2 0.2"/>
      </geometry>
      <material name="LightGrey">
        <color rgba="0.7 0.7 0.7 1.0"/>
      </material>
    </visual>
    <collision>
      <geometry>
        <box size="0.2 0.2 0.2"/>
      </geometry>
    </collision>
    <inertial>
      <mass value="10"/>
      <origin rpy="0 0 0" xyz="0.0 0.0 0.0"/>
      <inertia ixx="0.0" ixy="0.0" ixz="0.0" iyy="0.0" iyz="0.0" izz="0.0"/>
    </inertial>
  </link>
  <gazebo reference="base_link">
    <material>Gazebo/Gray</material>
  </gazebo>


  <joint name="base_to_link1" type="continuous">
    <parent link="base_link"/>
    <child link="link1"/>
    <origin rpy="0.0 0.0 0.0" xyz="0.0 0.0 0.0"/>
    <axis xyz="0 0 1"/>
    <!--<limit effort="100.0" lower="-6.28" upper="6.28" velocity="3.2"/>-->
    <!--<limit effort="100.0" velocity="3.2"/>-->
    <dynamics damping="0.00" friction="0.0"/>
  </joint>
  <link name="link1">
    <visual>
      <geometry>
        <box size="0.1 1 0.1"/>
      </geometry>
	  <origin rpy="0 0 0" xyz="0 0.5 0"/>
      <material name="red">
        <color rgba="1 0 0 1.0"/>
      </material>
    </visual>
    <collision>
      <geometry>
        <box size="0.1 1 0.1"/>
      </geometry>
	  <origin rpy="0 0 0" xyz="0 0.5 0"/>
    </collision>
    <inertial>
      <mass value="4"/>
      <origin rpy="0 0 0" xyz="0.0 0.5 0.0"/>
      <inertia ixx="0.0" ixy="0.0" ixz="0.0" iyy="0.0" iyz="0.0" izz="0.0"/>
    </inertial>
  </link>
  <gazebo reference="link1">
    <material>Gazebo/Red</material>
  </gazebo>

  <transmission name="base_to_link1_trans">
    <type>transmission_interface/SimpleTransmission</type>
    <joint name="base_to_link1">
      <hardwareInterface>hardware_interface/EffortJointInterface</hardwareInterface>
      <!--<hardwareInterface>hardware_interface/VelocityJointInterface</hardwareInterface>-->
    </joint>
    <actuator name="base_to_link1_motor">
      <mechanicalReduction>1</mechanicalReduction>
    </actuator>
  </transmission>

</robot>
